<?xml version="1.0"?>
<robot name="two_link_robot">
  <!--Links-->
  <link name="link_1">
    <visual>
      <geometry>
        <cylinder length="0.5" radius="0.2"/>
      </geometry>
    </visual>
  </link>

  <link name="link_2">
    <visual>
      <geometry>
        <box size="0.6 0.1 0.2"/>
      </geometry>
    </visual>
  </link>

  <!--Joints-->
  <joint name="joint_1" type="revolute">
    <parent link="link_1"/>
    <child link="link_2"/>
    <origin xyz="0.0 0.0 0.35" rpy="0.0 0.0 0.0"/>
    <axis xyz="0.0 0.0 1.0"/>
    <limit lower="1" upper="2" effort="0.0" velocity="0.0"/>
  </joint>
</robot>
